apscheduler.scheduler - INFO - Scheduler started
telegram.ext.updater - INFO - Received signal 2 (SIGINT), stopping...
apscheduler.scheduler - INFO - Scheduler has been shut down
apscheduler.scheduler - INFO - Scheduler started
telegram.ext.updater - INFO - Received signal 2 (SIGINT), stopping...
apscheduler.scheduler - INFO - Scheduler has been shut down
apscheduler.scheduler - INFO - Scheduler started
telegram.ext.updater - INFO - Received signal 2 (SIGINT), stopping...
apscheduler.scheduler - INFO - Scheduler has been shut down
apscheduler.scheduler - INFO - Scheduler started
telegram.ext.updater - INFO - Received signal 2 (SIGINT), stopping...
apscheduler.scheduler - INFO - Scheduler has been shut down
apscheduler.scheduler - INFO - Scheduler started
telegram.ext.updater - INFO - Received signal 2 (SIGINT), stopping...
apscheduler.scheduler - INFO - Scheduler has been shut down
apscheduler.scheduler - INFO - Scheduler started
telegram.ext.updater - INFO - Received signal 2 (SIGINT), stopping...
apscheduler.scheduler - INFO - Scheduler has been shut down
apscheduler.scheduler - INFO - Scheduler started
telegram.ext.updater - INFO - Received signal 2 (SIGINT), stopping...
apscheduler.scheduler - INFO - Scheduler has been shut down
apscheduler.scheduler - INFO - Scheduler started
telegram.ext.dispatcher - ERROR - No error handlers are registered, logging exception.
Traceback (most recent call last):
  File "C:\Users\Nikolay Olta\AppData\Local\Programs\Python\Python311\Lib\site-packages\telegram\ext\dispatcher.py", line 557, in process_update
    handler.handle_update(update, self, check, context)
  File "C:\Users\Nikolay Olta\AppData\Local\Programs\Python\Python311\Lib\site-packages\telegram\ext\handler.py", line 199, in handle_update
    return self.callback(update, context)
           ^^^^^^^^^^^^^^^^^^^^^^^^^^^^^^
  File "C:\projects\lesson2\8_ephem_bot.py", line 43, in talk_to_me
    if user_text in ephem:
       ^^^^^^^^^^^^^^^^^^
TypeError: argument of type 'module' is not iterable
telegram.ext.dispatcher - ERROR - No error handlers are registered, logging exception.
Traceback (most recent call last):
  File "C:\Users\Nikolay Olta\AppData\Local\Programs\Python\Python311\Lib\site-packages\telegram\ext\dispatcher.py", line 557, in process_update
    handler.handle_update(update, self, check, context)
  File "C:\Users\Nikolay Olta\AppData\Local\Programs\Python\Python311\Lib\site-packages\telegram\ext\handler.py", line 199, in handle_update
    return self.callback(update, context)
           ^^^^^^^^^^^^^^^^^^^^^^^^^^^^^^
  File "C:\projects\lesson2\8_ephem_bot.py", line 43, in talk_to_me
    if user_text in ephem:
       ^^^^^^^^^^^^^^^^^^
TypeError: argument of type 'module' is not iterable
telegram.ext.dispatcher - ERROR - No error handlers are registered, logging exception.
Traceback (most recent call last):
  File "C:\Users\Nikolay Olta\AppData\Local\Programs\Python\Python311\Lib\site-packages\telegram\ext\dispatcher.py", line 557, in process_update
    handler.handle_update(update, self, check, context)
  File "C:\Users\Nikolay Olta\AppData\Local\Programs\Python\Python311\Lib\site-packages\telegram\ext\handler.py", line 199, in handle_update
    return self.callback(update, context)
           ^^^^^^^^^^^^^^^^^^^^^^^^^^^^^^
  File "C:\projects\lesson2\8_ephem_bot.py", line 43, in talk_to_me
    if user_text in ephem:
       ^^^^^^^^^^^^^^^^^^
TypeError: argument of type 'module' is not iterable
telegram.ext.dispatcher - ERROR - No error handlers are registered, logging exception.
Traceback (most recent call last):
  File "C:\Users\Nikolay Olta\AppData\Local\Programs\Python\Python311\Lib\site-packages\telegram\ext\dispatcher.py", line 557, in process_update
    handler.handle_update(update, self, check, context)
  File "C:\Users\Nikolay Olta\AppData\Local\Programs\Python\Python311\Lib\site-packages\telegram\ext\handler.py", line 199, in handle_update
    return self.callback(update, context)
           ^^^^^^^^^^^^^^^^^^^^^^^^^^^^^^
  File "C:\projects\lesson2\8_ephem_bot.py", line 43, in talk_to_me
    if user_text in ephem:
       ^^^^^^^^^^^^^^^^^^
TypeError: argument of type 'module' is not iterable
telegram.ext.dispatcher - ERROR - No error handlers are registered, logging exception.
Traceback (most recent call last):
  File "C:\Users\Nikolay Olta\AppData\Local\Programs\Python\Python311\Lib\site-packages\telegram\ext\dispatcher.py", line 557, in process_update
    handler.handle_update(update, self, check, context)
  File "C:\Users\Nikolay Olta\AppData\Local\Programs\Python\Python311\Lib\site-packages\telegram\ext\handler.py", line 199, in handle_update
    return self.callback(update, context)
           ^^^^^^^^^^^^^^^^^^^^^^^^^^^^^^
  File "C:\projects\lesson2\8_ephem_bot.py", line 43, in talk_to_me
    if user_text in ephem:
       ^^^^^^^^^^^^^^^^^^
TypeError: argument of type 'module' is not iterable
telegram.ext.dispatcher - ERROR - No error handlers are registered, logging exception.
Traceback (most recent call last):
  File "C:\Users\Nikolay Olta\AppData\Local\Programs\Python\Python311\Lib\site-packages\telegram\ext\dispatcher.py", line 557, in process_update
    handler.handle_update(update, self, check, context)
  File "C:\Users\Nikolay Olta\AppData\Local\Programs\Python\Python311\Lib\site-packages\telegram\ext\handler.py", line 199, in handle_update
    return self.callback(update, context)
           ^^^^^^^^^^^^^^^^^^^^^^^^^^^^^^
  File "C:\projects\lesson2\8_ephem_bot.py", line 43, in talk_to_me
    if user_text in ephem:
       ^^^^^^^^^^^^^^^^^^
TypeError: argument of type 'module' is not iterable
telegram.ext.updater - INFO - Received signal 2 (SIGINT), stopping...
apscheduler.scheduler - INFO - Scheduler has been shut down
apscheduler.scheduler - INFO - Scheduler started
telegram.ext.dispatcher - ERROR - No error handlers are registered, logging exception.
Traceback (most recent call last):
  File "C:\Users\Nikolay Olta\AppData\Local\Programs\Python\Python311\Lib\site-packages\telegram\ext\dispatcher.py", line 557, in process_update
    handler.handle_update(update, self, check, context)
  File "C:\Users\Nikolay Olta\AppData\Local\Programs\Python\Python311\Lib\site-packages\telegram\ext\handler.py", line 199, in handle_update
    return self.callback(update, context)
           ^^^^^^^^^^^^^^^^^^^^^^^^^^^^^^
  File "C:\projects\lesson2\8_ephem_bot.py", line 49, in name_planet
    planet = update.message.text.split[1]
             ~~~~~~~~~~~~~~~~~~~~~~~~~^^^
TypeError: 'builtin_function_or_method' object is not subscriptable
telegram.ext.dispatcher - ERROR - No error handlers are registered, logging exception.
Traceback (most recent call last):
  File "C:\Users\Nikolay Olta\AppData\Local\Programs\Python\Python311\Lib\site-packages\telegram\ext\dispatcher.py", line 557, in process_update
    handler.handle_update(update, self, check, context)
  File "C:\Users\Nikolay Olta\AppData\Local\Programs\Python\Python311\Lib\site-packages\telegram\ext\handler.py", line 199, in handle_update
    return self.callback(update, context)
           ^^^^^^^^^^^^^^^^^^^^^^^^^^^^^^
  File "C:\projects\lesson2\8_ephem_bot.py", line 49, in name_planet
    planet = update.message.text.split[1]
             ~~~~~~~~~~~~~~~~~~~~~~~~~^^^
TypeError: 'builtin_function_or_method' object is not subscriptable
telegram.ext.dispatcher - ERROR - No error handlers are registered, logging exception.
Traceback (most recent call last):
  File "C:\Users\Nikolay Olta\AppData\Local\Programs\Python\Python311\Lib\site-packages\telegram\ext\dispatcher.py", line 557, in process_update
    handler.handle_update(update, self, check, context)
  File "C:\Users\Nikolay Olta\AppData\Local\Programs\Python\Python311\Lib\site-packages\telegram\ext\handler.py", line 199, in handle_update
    return self.callback(update, context)
           ^^^^^^^^^^^^^^^^^^^^^^^^^^^^^^
  File "C:\projects\lesson2\8_ephem_bot.py", line 49, in name_planet
    planet = update.message.text.split[1]
             ~~~~~~~~~~~~~~~~~~~~~~~~~^^^
TypeError: 'builtin_function_or_method' object is not subscriptable
telegram.ext.updater - INFO - Received signal 2 (SIGINT), stopping...
apscheduler.scheduler - INFO - Scheduler has been shut down
apscheduler.scheduler - INFO - Scheduler started
telegram.ext.dispatcher - ERROR - No error handlers are registered, logging exception.
Traceback (most recent call last):
  File "C:\Users\Nikolay Olta\AppData\Local\Programs\Python\Python311\Lib\site-packages\telegram\ext\dispatcher.py", line 557, in process_update
    handler.handle_update(update, self, check, context)
  File "C:\Users\Nikolay Olta\AppData\Local\Programs\Python\Python311\Lib\site-packages\telegram\ext\handler.py", line 199, in handle_update
    return self.callback(update, context)
           ^^^^^^^^^^^^^^^^^^^^^^^^^^^^^^
  File "C:\projects\lesson2\8_ephem_bot.py", line 53, in name_planet
    planet = update.message.text.split[1]
             ~~~~~~~~~~~~~~~~~~~~~~~~~^^^
TypeError: 'builtin_function_or_method' object is not subscriptable
telegram.ext.dispatcher - ERROR - No error handlers are registered, logging exception.
Traceback (most recent call last):
  File "C:\Users\Nikolay Olta\AppData\Local\Programs\Python\Python311\Lib\site-packages\telegram\ext\dispatcher.py", line 557, in process_update
    handler.handle_update(update, self, check, context)
  File "C:\Users\Nikolay Olta\AppData\Local\Programs\Python\Python311\Lib\site-packages\telegram\ext\handler.py", line 199, in handle_update
    return self.callback(update, context)
           ^^^^^^^^^^^^^^^^^^^^^^^^^^^^^^
  File "C:\projects\lesson2\8_ephem_bot.py", line 53, in name_planet
    planet = update.message.text.split[1]
             ~~~~~~~~~~~~~~~~~~~~~~~~~^^^
TypeError: 'builtin_function_or_method' object is not subscriptable
telegram.ext.updater - INFO - Received signal 2 (SIGINT), stopping...
apscheduler.scheduler - INFO - Scheduler has been shut down
apscheduler.scheduler - INFO - Scheduler started
telegram.ext.dispatcher - ERROR - No error handlers are registered, logging exception.
Traceback (most recent call last):
  File "C:\Users\Nikolay Olta\AppData\Local\Programs\Python\Python311\Lib\site-packages\telegram\ext\dispatcher.py", line 557, in process_update
    handler.handle_update(update, self, check, context)
  File "C:\Users\Nikolay Olta\AppData\Local\Programs\Python\Python311\Lib\site-packages\telegram\ext\handler.py", line 199, in handle_update
    return self.callback(update, context)
           ^^^^^^^^^^^^^^^^^^^^^^^^^^^^^^
  File "C:\projects\lesson2\8_ephem_bot.py", line 53, in name_planet
    planet = update.message.text.split[1]
             ~~~~~~~~~~~~~~~~~~~~~~~~~^^^
TypeError: 'builtin_function_or_method' object is not subscriptable
telegram.ext.updater - INFO - Received signal 2 (SIGINT), stopping...
apscheduler.scheduler - INFO - Scheduler has been shut down
apscheduler.scheduler - INFO - Scheduler started
telegram.ext.dispatcher - ERROR - No error handlers are registered, logging exception.
Traceback (most recent call last):
  File "C:\Users\Nikolay Olta\AppData\Local\Programs\Python\Python311\Lib\site-packages\telegram\ext\dispatcher.py", line 557, in process_update
    handler.handle_update(update, self, check, context)
  File "C:\Users\Nikolay Olta\AppData\Local\Programs\Python\Python311\Lib\site-packages\telegram\ext\handler.py", line 199, in handle_update
    return self.callback(update, context)
           ^^^^^^^^^^^^^^^^^^^^^^^^^^^^^^
  File "C:\projects\lesson2\8_ephem_bot.py", line 53, in name_planet
    planet = update.message.text.split[1]
             ~~~~~~~~~~~~~~~~~~~~~~~~~^^^
TypeError: 'builtin_function_or_method' object is not subscriptable
telegram.ext.updater - INFO - Received signal 2 (SIGINT), stopping...
apscheduler.scheduler - INFO - Scheduler has been shut down
apscheduler.scheduler - INFO - Scheduler started
telegram.ext.dispatcher - ERROR - No error handlers are registered, logging exception.
Traceback (most recent call last):
  File "C:\Users\Nikolay Olta\AppData\Local\Programs\Python\Python311\Lib\site-packages\telegram\ext\dispatcher.py", line 557, in process_update
    handler.handle_update(update, self, check, context)
  File "C:\Users\Nikolay Olta\AppData\Local\Programs\Python\Python311\Lib\site-packages\telegram\ext\handler.py", line 199, in handle_update
    return self.callback(update, context)
           ^^^^^^^^^^^^^^^^^^^^^^^^^^^^^^
  File "C:\projects\lesson2\8_ephem_bot.py", line 52, in name_planet
    planet = update.message.text.split[1]
             ~~~~~~~~~~~~~~~~~~~~~~~~~^^^
TypeError: 'builtin_function_or_method' object is not subscriptable
telegram.ext.dispatcher - ERROR - No error handlers are registered, logging exception.
Traceback (most recent call last):
  File "C:\Users\Nikolay Olta\AppData\Local\Programs\Python\Python311\Lib\site-packages\telegram\ext\dispatcher.py", line 557, in process_update
    handler.handle_update(update, self, check, context)
  File "C:\Users\Nikolay Olta\AppData\Local\Programs\Python\Python311\Lib\site-packages\telegram\ext\handler.py", line 199, in handle_update
    return self.callback(update, context)
           ^^^^^^^^^^^^^^^^^^^^^^^^^^^^^^
  File "C:\projects\lesson2\8_ephem_bot.py", line 52, in name_planet
    planet = update.message.text.split[1]
             ~~~~~~~~~~~~~~~~~~~~~~~~~^^^
TypeError: 'builtin_function_or_method' object is not subscriptable
telegram.ext.dispatcher - ERROR - No error handlers are registered, logging exception.
Traceback (most recent call last):
  File "C:\Users\Nikolay Olta\AppData\Local\Programs\Python\Python311\Lib\site-packages\telegram\ext\dispatcher.py", line 557, in process_update
    handler.handle_update(update, self, check, context)
  File "C:\Users\Nikolay Olta\AppData\Local\Programs\Python\Python311\Lib\site-packages\telegram\ext\handler.py", line 199, in handle_update
    return self.callback(update, context)
           ^^^^^^^^^^^^^^^^^^^^^^^^^^^^^^
  File "C:\projects\lesson2\8_ephem_bot.py", line 52, in name_planet
    planet = update.message.text.split[1]
             ~~~~~~~~~~~~~~~~~~~~~~~~~^^^
TypeError: 'builtin_function_or_method' object is not subscriptable
telegram.ext.updater - ERROR - Error while getting Updates: Conflict: terminated by other getUpdates request; make sure that only one bot instance is running
telegram.ext.dispatcher - ERROR - No error handlers are registered, logging exception.
Traceback (most recent call last):
  File "C:\Users\Nikolay Olta\AppData\Local\Programs\Python\Python311\Lib\site-packages\telegram\ext\updater.py", line 651, in _network_loop_retry
    if not action_cb():
           ^^^^^^^^^^^
  File "C:\Users\Nikolay Olta\AppData\Local\Programs\Python\Python311\Lib\site-packages\telegram\ext\updater.py", line 602, in polling_action_cb
    updates = self.bot.get_updates(
              ^^^^^^^^^^^^^^^^^^^^^
  File "C:\Users\Nikolay Olta\AppData\Local\Programs\Python\Python311\Lib\site-packages\telegram\ext\extbot.py", line 228, in get_updates
    updates = super().get_updates(
              ^^^^^^^^^^^^^^^^^^^^
  File "C:\Users\Nikolay Olta\AppData\Local\Programs\Python\Python311\Lib\site-packages\telegram\bot.py", line 134, in decorator
    result = func(*args, **kwargs)
             ^^^^^^^^^^^^^^^^^^^^^
  File "C:\Users\Nikolay Olta\AppData\Local\Programs\Python\Python311\Lib\site-packages\telegram\bot.py", line 3140, in get_updates
    self._post(
  File "C:\Users\Nikolay Olta\AppData\Local\Programs\Python\Python311\Lib\site-packages\telegram\bot.py", line 299, in _post
    return self.request.post(
           ^^^^^^^^^^^^^^^^^^
  File "C:\Users\Nikolay Olta\AppData\Local\Programs\Python\Python311\Lib\site-packages\telegram\utils\request.py", line 361, in post
    result = self._request_wrapper(
             ^^^^^^^^^^^^^^^^^^^^^^
  File "C:\Users\Nikolay Olta\AppData\Local\Programs\Python\Python311\Lib\site-packages\telegram\utils\request.py", line 283, in _request_wrapper
    raise Conflict(message)
telegram.error.Conflict: Conflict: terminated by other getUpdates request; make sure that only one bot instance is running
telegram.ext.updater - ERROR - Error while getting Updates: Conflict: terminated by other getUpdates request; make sure that only one bot instance is running
telegram.ext.dispatcher - ERROR - No error handlers are registered, logging exception.
Traceback (most recent call last):
  File "C:\Users\Nikolay Olta\AppData\Local\Programs\Python\Python311\Lib\site-packages\telegram\ext\updater.py", line 651, in _network_loop_retry
    if not action_cb():
           ^^^^^^^^^^^
  File "C:\Users\Nikolay Olta\AppData\Local\Programs\Python\Python311\Lib\site-packages\telegram\ext\updater.py", line 602, in polling_action_cb
    updates = self.bot.get_updates(
              ^^^^^^^^^^^^^^^^^^^^^
  File "C:\Users\Nikolay Olta\AppData\Local\Programs\Python\Python311\Lib\site-packages\telegram\ext\extbot.py", line 228, in get_updates
    updates = super().get_updates(
              ^^^^^^^^^^^^^^^^^^^^
  File "C:\Users\Nikolay Olta\AppData\Local\Programs\Python\Python311\Lib\site-packages\telegram\bot.py", line 134, in decorator
    result = func(*args, **kwargs)
             ^^^^^^^^^^^^^^^^^^^^^
  File "C:\Users\Nikolay Olta\AppData\Local\Programs\Python\Python311\Lib\site-packages\telegram\bot.py", line 3140, in get_updates
    self._post(
  File "C:\Users\Nikolay Olta\AppData\Local\Programs\Python\Python311\Lib\site-packages\telegram\bot.py", line 299, in _post
    return self.request.post(
           ^^^^^^^^^^^^^^^^^^
  File "C:\Users\Nikolay Olta\AppData\Local\Programs\Python\Python311\Lib\site-packages\telegram\utils\request.py", line 361, in post
    result = self._request_wrapper(
             ^^^^^^^^^^^^^^^^^^^^^^
  File "C:\Users\Nikolay Olta\AppData\Local\Programs\Python\Python311\Lib\site-packages\telegram\utils\request.py", line 283, in _request_wrapper
    raise Conflict(message)
telegram.error.Conflict: Conflict: terminated by other getUpdates request; make sure that only one bot instance is running
telegram.ext.updater - ERROR - Error while getting Updates: Conflict: terminated by other getUpdates request; make sure that only one bot instance is running
telegram.ext.dispatcher - ERROR - No error handlers are registered, logging exception.
Traceback (most recent call last):
  File "C:\Users\Nikolay Olta\AppData\Local\Programs\Python\Python311\Lib\site-packages\telegram\ext\updater.py", line 651, in _network_loop_retry
    if not action_cb():
           ^^^^^^^^^^^
  File "C:\Users\Nikolay Olta\AppData\Local\Programs\Python\Python311\Lib\site-packages\telegram\ext\updater.py", line 602, in polling_action_cb
    updates = self.bot.get_updates(
              ^^^^^^^^^^^^^^^^^^^^^
  File "C:\Users\Nikolay Olta\AppData\Local\Programs\Python\Python311\Lib\site-packages\telegram\ext\extbot.py", line 228, in get_updates
    updates = super().get_updates(
              ^^^^^^^^^^^^^^^^^^^^
  File "C:\Users\Nikolay Olta\AppData\Local\Programs\Python\Python311\Lib\site-packages\telegram\bot.py", line 134, in decorator
    result = func(*args, **kwargs)
             ^^^^^^^^^^^^^^^^^^^^^
  File "C:\Users\Nikolay Olta\AppData\Local\Programs\Python\Python311\Lib\site-packages\telegram\bot.py", line 3140, in get_updates
    self._post(
  File "C:\Users\Nikolay Olta\AppData\Local\Programs\Python\Python311\Lib\site-packages\telegram\bot.py", line 299, in _post
    return self.request.post(
           ^^^^^^^^^^^^^^^^^^
  File "C:\Users\Nikolay Olta\AppData\Local\Programs\Python\Python311\Lib\site-packages\telegram\utils\request.py", line 361, in post
    result = self._request_wrapper(
             ^^^^^^^^^^^^^^^^^^^^^^
  File "C:\Users\Nikolay Olta\AppData\Local\Programs\Python\Python311\Lib\site-packages\telegram\utils\request.py", line 283, in _request_wrapper
    raise Conflict(message)
telegram.error.Conflict: Conflict: terminated by other getUpdates request; make sure that only one bot instance is running
telegram.ext.updater - ERROR - Error while getting Updates: Conflict: terminated by other getUpdates request; make sure that only one bot instance is running
telegram.ext.dispatcher - ERROR - No error handlers are registered, logging exception.
Traceback (most recent call last):
  File "C:\Users\Nikolay Olta\AppData\Local\Programs\Python\Python311\Lib\site-packages\telegram\ext\updater.py", line 651, in _network_loop_retry
    if not action_cb():
           ^^^^^^^^^^^
  File "C:\Users\Nikolay Olta\AppData\Local\Programs\Python\Python311\Lib\site-packages\telegram\ext\updater.py", line 602, in polling_action_cb
    updates = self.bot.get_updates(
              ^^^^^^^^^^^^^^^^^^^^^
  File "C:\Users\Nikolay Olta\AppData\Local\Programs\Python\Python311\Lib\site-packages\telegram\ext\extbot.py", line 228, in get_updates
    updates = super().get_updates(
              ^^^^^^^^^^^^^^^^^^^^
  File "C:\Users\Nikolay Olta\AppData\Local\Programs\Python\Python311\Lib\site-packages\telegram\bot.py", line 134, in decorator
    result = func(*args, **kwargs)
             ^^^^^^^^^^^^^^^^^^^^^
  File "C:\Users\Nikolay Olta\AppData\Local\Programs\Python\Python311\Lib\site-packages\telegram\bot.py", line 3140, in get_updates
    self._post(
  File "C:\Users\Nikolay Olta\AppData\Local\Programs\Python\Python311\Lib\site-packages\telegram\bot.py", line 299, in _post
    return self.request.post(
           ^^^^^^^^^^^^^^^^^^
  File "C:\Users\Nikolay Olta\AppData\Local\Programs\Python\Python311\Lib\site-packages\telegram\utils\request.py", line 361, in post
    result = self._request_wrapper(
             ^^^^^^^^^^^^^^^^^^^^^^
  File "C:\Users\Nikolay Olta\AppData\Local\Programs\Python\Python311\Lib\site-packages\telegram\utils\request.py", line 283, in _request_wrapper
    raise Conflict(message)
telegram.error.Conflict: Conflict: terminated by other getUpdates request; make sure that only one bot instance is running
telegram.ext.updater - ERROR - Error while getting Updates: Conflict: terminated by other getUpdates request; make sure that only one bot instance is running
telegram.ext.dispatcher - ERROR - No error handlers are registered, logging exception.
Traceback (most recent call last):
  File "C:\Users\Nikolay Olta\AppData\Local\Programs\Python\Python311\Lib\site-packages\telegram\ext\updater.py", line 651, in _network_loop_retry
    if not action_cb():
           ^^^^^^^^^^^
  File "C:\Users\Nikolay Olta\AppData\Local\Programs\Python\Python311\Lib\site-packages\telegram\ext\updater.py", line 602, in polling_action_cb
    updates = self.bot.get_updates(
              ^^^^^^^^^^^^^^^^^^^^^
  File "C:\Users\Nikolay Olta\AppData\Local\Programs\Python\Python311\Lib\site-packages\telegram\ext\extbot.py", line 228, in get_updates
    updates = super().get_updates(
              ^^^^^^^^^^^^^^^^^^^^
  File "C:\Users\Nikolay Olta\AppData\Local\Programs\Python\Python311\Lib\site-packages\telegram\bot.py", line 134, in decorator
    result = func(*args, **kwargs)
             ^^^^^^^^^^^^^^^^^^^^^
  File "C:\Users\Nikolay Olta\AppData\Local\Programs\Python\Python311\Lib\site-packages\telegram\bot.py", line 3140, in get_updates
    self._post(
  File "C:\Users\Nikolay Olta\AppData\Local\Programs\Python\Python311\Lib\site-packages\telegram\bot.py", line 299, in _post
    return self.request.post(
           ^^^^^^^^^^^^^^^^^^
  File "C:\Users\Nikolay Olta\AppData\Local\Programs\Python\Python311\Lib\site-packages\telegram\utils\request.py", line 361, in post
    result = self._request_wrapper(
             ^^^^^^^^^^^^^^^^^^^^^^
  File "C:\Users\Nikolay Olta\AppData\Local\Programs\Python\Python311\Lib\site-packages\telegram\utils\request.py", line 283, in _request_wrapper
    raise Conflict(message)
telegram.error.Conflict: Conflict: terminated by other getUpdates request; make sure that only one bot instance is running
telegram.ext.updater - ERROR - Error while getting Updates: Conflict: terminated by other getUpdates request; make sure that only one bot instance is running
telegram.ext.dispatcher - ERROR - No error handlers are registered, logging exception.
Traceback (most recent call last):
  File "C:\Users\Nikolay Olta\AppData\Local\Programs\Python\Python311\Lib\site-packages\telegram\ext\updater.py", line 651, in _network_loop_retry
    if not action_cb():
           ^^^^^^^^^^^
  File "C:\Users\Nikolay Olta\AppData\Local\Programs\Python\Python311\Lib\site-packages\telegram\ext\updater.py", line 602, in polling_action_cb
    updates = self.bot.get_updates(
              ^^^^^^^^^^^^^^^^^^^^^
  File "C:\Users\Nikolay Olta\AppData\Local\Programs\Python\Python311\Lib\site-packages\telegram\ext\extbot.py", line 228, in get_updates
    updates = super().get_updates(
              ^^^^^^^^^^^^^^^^^^^^
  File "C:\Users\Nikolay Olta\AppData\Local\Programs\Python\Python311\Lib\site-packages\telegram\bot.py", line 134, in decorator
    result = func(*args, **kwargs)
             ^^^^^^^^^^^^^^^^^^^^^
  File "C:\Users\Nikolay Olta\AppData\Local\Programs\Python\Python311\Lib\site-packages\telegram\bot.py", line 3140, in get_updates
    self._post(
  File "C:\Users\Nikolay Olta\AppData\Local\Programs\Python\Python311\Lib\site-packages\telegram\bot.py", line 299, in _post
    return self.request.post(
           ^^^^^^^^^^^^^^^^^^
  File "C:\Users\Nikolay Olta\AppData\Local\Programs\Python\Python311\Lib\site-packages\telegram\utils\request.py", line 361, in post
    result = self._request_wrapper(
             ^^^^^^^^^^^^^^^^^^^^^^
  File "C:\Users\Nikolay Olta\AppData\Local\Programs\Python\Python311\Lib\site-packages\telegram\utils\request.py", line 283, in _request_wrapper
    raise Conflict(message)
telegram.error.Conflict: Conflict: terminated by other getUpdates request; make sure that only one bot instance is running
telegram.ext.updater - ERROR - Error while getting Updates: Conflict: terminated by other getUpdates request; make sure that only one bot instance is running
telegram.ext.dispatcher - ERROR - No error handlers are registered, logging exception.
Traceback (most recent call last):
  File "C:\Users\Nikolay Olta\AppData\Local\Programs\Python\Python311\Lib\site-packages\telegram\ext\updater.py", line 651, in _network_loop_retry
    if not action_cb():
           ^^^^^^^^^^^
  File "C:\Users\Nikolay Olta\AppData\Local\Programs\Python\Python311\Lib\site-packages\telegram\ext\updater.py", line 602, in polling_action_cb
    updates = self.bot.get_updates(
              ^^^^^^^^^^^^^^^^^^^^^
  File "C:\Users\Nikolay Olta\AppData\Local\Programs\Python\Python311\Lib\site-packages\telegram\ext\extbot.py", line 228, in get_updates
    updates = super().get_updates(
              ^^^^^^^^^^^^^^^^^^^^
  File "C:\Users\Nikolay Olta\AppData\Local\Programs\Python\Python311\Lib\site-packages\telegram\bot.py", line 134, in decorator
    result = func(*args, **kwargs)
             ^^^^^^^^^^^^^^^^^^^^^
  File "C:\Users\Nikolay Olta\AppData\Local\Programs\Python\Python311\Lib\site-packages\telegram\bot.py", line 3140, in get_updates
    self._post(
  File "C:\Users\Nikolay Olta\AppData\Local\Programs\Python\Python311\Lib\site-packages\telegram\bot.py", line 299, in _post
    return self.request.post(
           ^^^^^^^^^^^^^^^^^^
  File "C:\Users\Nikolay Olta\AppData\Local\Programs\Python\Python311\Lib\site-packages\telegram\utils\request.py", line 361, in post
    result = self._request_wrapper(
             ^^^^^^^^^^^^^^^^^^^^^^
  File "C:\Users\Nikolay Olta\AppData\Local\Programs\Python\Python311\Lib\site-packages\telegram\utils\request.py", line 283, in _request_wrapper
    raise Conflict(message)
telegram.error.Conflict: Conflict: terminated by other getUpdates request; make sure that only one bot instance is running
telegram.ext.updater - ERROR - Error while getting Updates: Conflict: terminated by other getUpdates request; make sure that only one bot instance is running
telegram.ext.dispatcher - ERROR - No error handlers are registered, logging exception.
Traceback (most recent call last):
  File "C:\Users\Nikolay Olta\AppData\Local\Programs\Python\Python311\Lib\site-packages\telegram\ext\updater.py", line 651, in _network_loop_retry
    if not action_cb():
           ^^^^^^^^^^^
  File "C:\Users\Nikolay Olta\AppData\Local\Programs\Python\Python311\Lib\site-packages\telegram\ext\updater.py", line 602, in polling_action_cb
    updates = self.bot.get_updates(
              ^^^^^^^^^^^^^^^^^^^^^
  File "C:\Users\Nikolay Olta\AppData\Local\Programs\Python\Python311\Lib\site-packages\telegram\ext\extbot.py", line 228, in get_updates
    updates = super().get_updates(
              ^^^^^^^^^^^^^^^^^^^^
  File "C:\Users\Nikolay Olta\AppData\Local\Programs\Python\Python311\Lib\site-packages\telegram\bot.py", line 134, in decorator
    result = func(*args, **kwargs)
             ^^^^^^^^^^^^^^^^^^^^^
  File "C:\Users\Nikolay Olta\AppData\Local\Programs\Python\Python311\Lib\site-packages\telegram\bot.py", line 3140, in get_updates
    self._post(
  File "C:\Users\Nikolay Olta\AppData\Local\Programs\Python\Python311\Lib\site-packages\telegram\bot.py", line 299, in _post
    return self.request.post(
           ^^^^^^^^^^^^^^^^^^
  File "C:\Users\Nikolay Olta\AppData\Local\Programs\Python\Python311\Lib\site-packages\telegram\utils\request.py", line 361, in post
    result = self._request_wrapper(
             ^^^^^^^^^^^^^^^^^^^^^^
  File "C:\Users\Nikolay Olta\AppData\Local\Programs\Python\Python311\Lib\site-packages\telegram\utils\request.py", line 283, in _request_wrapper
    raise Conflict(message)
telegram.error.Conflict: Conflict: terminated by other getUpdates request; make sure that only one bot instance is running
telegram.ext.updater - ERROR - Error while getting Updates: Conflict: terminated by other getUpdates request; make sure that only one bot instance is running
telegram.ext.dispatcher - ERROR - No error handlers are registered, logging exception.
Traceback (most recent call last):
  File "C:\Users\Nikolay Olta\AppData\Local\Programs\Python\Python311\Lib\site-packages\telegram\ext\updater.py", line 651, in _network_loop_retry
    if not action_cb():
           ^^^^^^^^^^^
  File "C:\Users\Nikolay Olta\AppData\Local\Programs\Python\Python311\Lib\site-packages\telegram\ext\updater.py", line 602, in polling_action_cb
    updates = self.bot.get_updates(
              ^^^^^^^^^^^^^^^^^^^^^
  File "C:\Users\Nikolay Olta\AppData\Local\Programs\Python\Python311\Lib\site-packages\telegram\ext\extbot.py", line 228, in get_updates
    updates = super().get_updates(
              ^^^^^^^^^^^^^^^^^^^^
  File "C:\Users\Nikolay Olta\AppData\Local\Programs\Python\Python311\Lib\site-packages\telegram\bot.py", line 134, in decorator
    result = func(*args, **kwargs)
             ^^^^^^^^^^^^^^^^^^^^^
  File "C:\Users\Nikolay Olta\AppData\Local\Programs\Python\Python311\Lib\site-packages\telegram\bot.py", line 3140, in get_updates
    self._post(
  File "C:\Users\Nikolay Olta\AppData\Local\Programs\Python\Python311\Lib\site-packages\telegram\bot.py", line 299, in _post
    return self.request.post(
           ^^^^^^^^^^^^^^^^^^
  File "C:\Users\Nikolay Olta\AppData\Local\Programs\Python\Python311\Lib\site-packages\telegram\utils\request.py", line 361, in post
    result = self._request_wrapper(
             ^^^^^^^^^^^^^^^^^^^^^^
  File "C:\Users\Nikolay Olta\AppData\Local\Programs\Python\Python311\Lib\site-packages\telegram\utils\request.py", line 283, in _request_wrapper
    raise Conflict(message)
telegram.error.Conflict: Conflict: terminated by other getUpdates request; make sure that only one bot instance is running
telegram.ext.updater - ERROR - Error while getting Updates: Conflict: terminated by other getUpdates request; make sure that only one bot instance is running
telegram.ext.dispatcher - ERROR - No error handlers are registered, logging exception.
Traceback (most recent call last):
  File "C:\Users\Nikolay Olta\AppData\Local\Programs\Python\Python311\Lib\site-packages\telegram\ext\updater.py", line 651, in _network_loop_retry
    if not action_cb():
           ^^^^^^^^^^^
  File "C:\Users\Nikolay Olta\AppData\Local\Programs\Python\Python311\Lib\site-packages\telegram\ext\updater.py", line 602, in polling_action_cb
    updates = self.bot.get_updates(
              ^^^^^^^^^^^^^^^^^^^^^
  File "C:\Users\Nikolay Olta\AppData\Local\Programs\Python\Python311\Lib\site-packages\telegram\ext\extbot.py", line 228, in get_updates
    updates = super().get_updates(
              ^^^^^^^^^^^^^^^^^^^^
  File "C:\Users\Nikolay Olta\AppData\Local\Programs\Python\Python311\Lib\site-packages\telegram\bot.py", line 134, in decorator
    result = func(*args, **kwargs)
             ^^^^^^^^^^^^^^^^^^^^^
  File "C:\Users\Nikolay Olta\AppData\Local\Programs\Python\Python311\Lib\site-packages\telegram\bot.py", line 3140, in get_updates
    self._post(
  File "C:\Users\Nikolay Olta\AppData\Local\Programs\Python\Python311\Lib\site-packages\telegram\bot.py", line 299, in _post
    return self.request.post(
           ^^^^^^^^^^^^^^^^^^
  File "C:\Users\Nikolay Olta\AppData\Local\Programs\Python\Python311\Lib\site-packages\telegram\utils\request.py", line 361, in post
    result = self._request_wrapper(
             ^^^^^^^^^^^^^^^^^^^^^^
  File "C:\Users\Nikolay Olta\AppData\Local\Programs\Python\Python311\Lib\site-packages\telegram\utils\request.py", line 283, in _request_wrapper
    raise Conflict(message)
telegram.error.Conflict: Conflict: terminated by other getUpdates request; make sure that only one bot instance is running
telegram.ext.updater - INFO - Received signal 2 (SIGINT), stopping...
apscheduler.scheduler - INFO - Scheduler has been shut down
